Traceback (most recent call last):
  File "/home/runner/workspace/.pythonlibs/lib/python3.11/site-packages/flask/app.py", line 917, in full_dispatch_request
    rv = self.dispatch_request()
         ^^^^^^^^^^^^^^^^^^^^^^^
  File "/home/runner/workspace/.pythonlibs/lib/python3.11/site-packages/flask/app.py", line 891, in dispatch_request
    self.raise_routing_exception(req)
  File "/home/runner/workspace/.pythonlibs/lib/python3.11/site-packages/flask/app.py", line 500, in raise_routing_exception
    raise request.routing_exception  # type: ignore[misc]
  File "/home/runner/workspace/.pythonlibs/lib/python3.11/site-packages/flask/ctx.py", line 362, in match_request
    result = self.url_adapter.match(return_rule=True)  # type: ignore
             ^^^^^^^^^^^^^^^^^^^^^^^^^^^^^^^^^^^^^^^^^^^^^^^^^^^^^^^^
  File "/home/runner/workspace/.pythonlibs/lib/python3.11/site-packages/werkzeug/routing/map.py", line 629, in match
    raise NotFound() from None
werkzeug.exceptions.NotFound: 404 Not Found: The requested URL was not found on the server. If you entered the URL manually please check your spelling and try again.

During handling of the above exception, another exception occurred:

Traceback (most recent call last):
  File "/home/runner/workspace/.pythonlibs/lib/python3.11/site-packages/flask/app.py", line 1536, in __call__
    return self.wsgi_app(environ, start_response)
           ^^^^^^^^^^^^^^^^^^^^^^^^^^^^^^^^^^^^^^
  File "/home/runner/workspace/.pythonlibs/lib/python3.11/site-packages/werkzeug/middleware/proxy_fix.py", line 183, in __call__
    return self.app(environ, start_response)
           ^^^^^^^^^^^^^^^^^^^^^^^^^^^^^^^^^
  File "/home/runner/workspace/.pythonlibs/lib/python3.11/site-packages/flask/app.py", line 1514, in wsgi_app
    response = self.handle_exception(e)
               ^^^^^^^^^^^^^^^^^^^^^^^^
  File "/home/runner/workspace/.pythonlibs/lib/python3.11/site-packages/flask/app.py", line 1511, in wsgi_app
    response = self.full_dispatch_request()
               ^^^^^^^^^^^^^^^^^^^^^^^^^^^^
  File "/home/runner/workspace/.pythonlibs/lib/python3.11/site-packages/flask/app.py", line 919, in full_dispatch_request
    rv = self.handle_user_exception(e)
         ^^^^^^^^^^^^^^^^^^^^^^^^^^^^^
  File "/home/runner/workspace/.pythonlibs/lib/python3.11/site-packages/flask/app.py", line 802, in handle_user_exception
    return self.handle_http_exception(e)
           ^^^^^^^^^^^^^^^^^^^^^^^^^^^^^
  File "/home/runner/workspace/.pythonlibs/lib/python3.11/site-packages/flask/app.py", line 777, in handle_http_exception
    return self.ensure_sync(handler)(e)  # type: ignore[no-any-return]
           ^^^^^^^^^^^^^^^^^^^^^^^^^^^^^^^^^^^^^^^^^^^^^^^^^^^^^^^^^^^
  File "/home/runner/workspace/app.py", line 62, in not_found
    return render_template('error/404.html'), 404
           ^^^^^^^^^^^^^^^^^^^^^^^^^^^^^^^^^^^^^^
NameError: name 'render_template' is not defined
INFO:werkzeug:172.31.94.162 - - [04/Aug/2025 01:07:33] "GET /?__debugger__=yes&cmd=resource&f=style.css HTTP/1.1" 304 -
INFO:werkzeug:172.31.94.162 - - [04/Aug/2025 01:07:33] "GET /?__debugger__=yes&cmd=resource&f=debugger.js HTTP/1.1" 304 -